<?xml version="1.0"?>
<robot name="ammr_main" xmlns:xacro="http://www.ros.org/wiki/xacro">

    <xacro:property name="wheels_radius" value="0.162"/>

    <!-- RIGHT DRIVE WHEEL LINK-->
    <link name="Diff_Wheel_Right_Link">
        <inertial>
            <origin xyz="1.73472347597681E-17 -8.32667268468867E-17 -0.00236500745899665" rpy="0 0 0" />
            <mass value="3.39203243164232" />
            <inertia
                ixx="0.0243089316503053"
                ixy="2.96346873108226E-18"
                ixz="3.25955054566999E-16"
                iyy="0.0243089316503053"
                iyz="3.64879542640916E-16"
                izz="0.047247796608228" />
        </inertial>
        <visual>
            <origin xyz="0 0 0" rpy="0 0 0" />
            <geometry>
                <mesh filename="file://$(find my_robot_hw)/meshes/Diff_Wheel_Right_Link.STL" />
            </geometry>
            <material name="">
                <color rgba="0.109803921568627 0.109803921568627 0.109803921568627 1" />
            </material>
        </visual>
        <collision>
            <origin xyz="0 0 0" rpy="0 0 0" />
            <geometry>
                <mesh filename="file://$(find my_robot_hw)/meshes/Diff_Wheel_Right_Link.STL" />
            </geometry>
        </collision>
    </link>
<!-- RIGHT DRIVE WHEEL JOINT-->
    <joint name="Diff_Wheel_Right_Joint" type="continuous">
        <origin xyz="-0.00499999999991857 -0.205600000454991 0.15515000000001" rpy="1.57079632679492 0 0" />
        <parent link="base_link" />
        <child link="Diff_Wheel_Right_Link" />
        <axis xyz="0 0 -1" />
    </joint>
<!-- LEFT DRIVE WHEEL LINK-->
    <link name="Diff_Wheel_Left_Link">
        <inertial>
            <origin xyz="3.81639164714898E-17 3.60822483003176E-16 0.0023650074589967" rpy="0 0 0" />
            <mass value="3.39203243164232" />
            <inertia
                ixx="0.0243089316503053"
                ixy="-7.91247792483322E-19"
                ixz="2.34751170342299E-16"
                iyy="0.0243089316503053"
                iyz="2.97199082724946E-15"
                izz="0.0472477966082281" />
        </inertial>
        <visual>
            <origin xyz="0 0 0" rpy="0 0 0" />
            <geometry>
                <mesh filename="file://$(find my_robot_hw)/meshes/Diff_Wheel_Left_Link.STL" />
            </geometry>
            <material name="">
                <color rgba="0.109803921568627 0.109803921568627 0.109803921568627 1" />
            </material>
        </visual>
        <collision>
            <origin xyz="0 0 0" rpy="0 0 0" />
            <geometry>
                <mesh filename="file://$(find my_robot_hw)/meshes/Diff_Wheel_Left_Link.STL" />
            </geometry>
        </collision>
    </link>
<!-- LEFT DRIVE WHEEL JOINT-->
    <joint name="Diff_Wheel_Left_Joint" type="continuous">
        <origin xyz="-0.00500000000008063 0.205599999544986 0.15515000000001" rpy="1.57079632679502 0 0" />
        <parent link="base_link" />
        <child link="Diff_Wheel_Left_Link" />
        <axis xyz="0 0 1" />
    </joint>

</robot>