<?xml version="1.0"?>
<robot name="ammr_main" xmlns:xacro="http://www.ros.org/wiki/xacro">
<!-- ROBOT ARM JOINT 1-->
    <!-- Robot arm Link 1 -->
    <link name="Manipulator_J1_Link">
        <inertial>
            <origin xyz="-0.00821912518927564 0.00204815917950716 0.0530925004865024" rpy="0 0 0" />
            <mass value="2.59329608264777" />
            <inertia
            ixx="0.00541011353910455"
            ixy="-0.000216772139965237"
            ixz="0.000471798412674179"
            iyy="0.00495712301252238"
            iyz="0.000104473121389477"
            izz="0.00758603560467172"/>
        </inertial>
        <visual>
            <origin xyz="0 0 0" rpy="0 0 0" />
            <geometry>
                <mesh filename="file://$(find my_robot_hw)/meshes/Manipulator_J1_Link.STL" />
            </geometry>
            <material name="">
                <color rgba="0.898039215686275 0.913725490196078 0.925490196078431 1" />
            </material>
        </visual>
        <collision>
            <origin xyz="0 0 0" rpy="0 0 0" />
            <geometry>
                <mesh filename="file://$(find my_robot_hw)/meshes/Manipulator_J1_Link.STL" />
            </geometry>
        </collision>
    </link>
    <!-- Robot arm Joint 1 -->
    <joint name="Manipulator_J1_Joint" type="revolute">
        <origin xyz="0.255 0 0.653" rpy="0 0 -${pi/2}" />
        <parent link="base_link" />
        <child link="Manipulator_J1_Link" />
        <axis xyz="0 0 1" />
        <limit
            lower="0.0"
            upper="${pi}"
            effort="1.0"
            velocity="1.0" />
    </joint>

<!-- ROBOT ARM JOINT 2-->
    <!-- Robot arm Link 2 -->
    <link name="Manipulator_J2_Link">
        <inertial>
            <origin xyz="0.267053886995787 0.000108408653894637 0.00531039785710827" rpy="0 0 0" />
            <mass value="3.17866225891483" />
            <inertia
                ixx="0.00510097938382117"
                ixy="-1.90695202185544E-05"
                ixz="0.000150913219587262"
                iyy="0.0246713642411258"
                iyz="-1.31724887039001E-05"
                izz="0.0264517819451547" />
        </inertial>
        <visual>
            <origin xyz="0 0 0" rpy="0 0 0" />
            <geometry>
                <mesh filename="file://$(find my_robot_hw)/meshes/Manipulator_J2_Link.STL" />
            </geometry>
            <material name="">
                <color rgba="0.929 0.298 0.337 1" />
            </material>
        </visual>
        <collision>
            <origin xyz="0 0 0" rpy="0 0 0" />
            <geometry>
                <mesh filename="file://$(find my_robot_hw)/meshes/Manipulator_J2_Link.STL" />
            </geometry>
        </collision>
    </link>
    <!-- Robot arm Joint 2 -->
    <joint name="Manipulator_J2_Joint" type="revolute">
        <origin xyz="-0.04 -0.108 0.08" rpy="${pi/2} 0 0" />
        <parent link="Manipulator_J1_Link" />
        <child link="Manipulator_J2_Link" />
        <axis xyz="0 0 1" />
        <limit
            lower="0.0"
            upper="${pi}"
            effort="1.0"
            velocity="1.0" />
    </joint>
<!-- ROBOT ARM JOINT 3-->
    <!-- Robot arm Link 3 -->
    <link name="Manipulator_J3_Link">
        <inertial>
            <origin xyz="-0.00297023342828062 0.0316613483285501 -0.0609222392688595" rpy="0 0 0" />
            <mass value="1.54404534783932" />
            <inertia
                ixx="0.00360881100635871"
                ixy="-0.000365956407239031"
                ixz="9.70609649563046E-05"
                iyy="0.00260274100910518"
                iyz="-0.000453070704768047"
                izz="0.00412877160144985"/>
        </inertial>
        <visual>
            <origin xyz="0 0 0" rpy="0 0 0" />
            <geometry>
                <mesh filename="file://$(find my_robot_hw)/meshes/Manipulator_J3_Link.STL" />
            </geometry>
            <material name="">
                <color rgba="1 1 1 1" />
            </material>
        </visual>
        <collision>
            <origin xyz="0 0 0" rpy="0 0 0" />
            <geometry>
                <mesh filename="file://$(find my_robot_hw)/meshes/Manipulator_J3_Link.STL" />
            </geometry>
        </collision>
    </link>
    <!-- Robot arm Joint 3 -->
    <joint name="Manipulator_J3_Joint" type="revolute">
        <origin xyz="0.499393172392654 0.000611508112408177 -0.0340566621432228" rpy="0 0 -${pi/4}" />
        <parent link="Manipulator_J2_Link" />
        <child link="Manipulator_J3_Link" />
        <axis xyz="0 0 1" />
        <limit
            lower="0.0"
            upper="${3*pi/4}"
            effort="1.0"
            velocity="1.0" />
    </joint>
<!-- ROBOT ARM JOINT 4-->
    <!-- Robot arm Link 4 -->
    <link name="Manipulator_J4_Link">
        <inertial>
            <origin xyz="-0.000720861551614882 0.00237545351844409 -0.168614004524069" rpy="0 0 0" />
            <mass value="2.29844422173324" />
            <inertia
                ixx="0.00537298640174416"
                ixy="-1.61013770094798E-06"
                ixz="-2.04587573496942E-06"
                iyy="0.00606700542588369"
                iyz="-4.54333969663953E-05"
                izz="0.00238609539282176" />
        </inertial>
        <visual>
            <origin xyz="0 0 0" rpy="0 0 0" />
            <geometry>
                <mesh filename="file://$(find my_robot_hw)/meshes/Manipulator_J4_Link.STL" />
            </geometry>
            <material name="">
                <color rgba="0.929 0.298 0.337 1" />
            </material>
        </visual>
        <collision>
            <origin xyz="0 0 0" rpy="0 0 0" />
            <geometry>
                <mesh filename="file://$(find my_robot_hw)/meshes/Manipulator_J4_Link.STL" />
            </geometry>
        </collision>
    </link>
    <!-- Robot arm Joint 4 -->
    <joint name="Manipulator_J4_Joint" type="revolute">
        <origin xyz="0.000606827739718652 -0.0511115081108 -0.0730433378567769" rpy="-${pi/2} -${pi/2} 0" />
        <parent link="Manipulator_J3_Link" />
        <child link="Manipulator_J4_Link" />
        <axis xyz="0 0 1" />
        <limit
            lower="0.0"
            upper="${pi}"
            effort="1.0"
            velocity="1.0" />
    </joint>
<!-- ROBOT ARM JOINT 5-->
    <!-- Robot arm Link 5 -->
    <link name="Manipulator_J5_Link">
        <inertial>
            <origin xyz="0.00178879766106144 -0.000310236861449487 -0.000178370435065474" rpy="0 0 0" />
            <mass value="0.636561947212399" />
            <inertia
                ixx="0.000541294060870965"
                ixy="6.60700326323958E-07"
                ixz="-3.66021693889605E-06"
                iyy="0.000669750749294487"
                iyz="1.45341979231307E-07"
                izz="0.000470024925666913" />
        </inertial>
        <visual>
            <origin xyz="0 0 0" rpy="0 0 0" />
            <geometry>
                <mesh filename="file://$(find my_robot_hw)/meshes/Manipulator_J5_Link.STL" />
            </geometry>
            <material name="">
                <color rgba="1 1 1 1" />
            </material>
        </visual>
        <collision>
            <origin xyz="0 0 0" rpy="0 0 0" />
            <geometry>
                <mesh filename="file://$(find my_robot_hw)/meshes/Manipulator_J5_Link.STL" />
            </geometry>
        </collision>
    </link>
    <!-- Robot arm Joint 5 -->
    <joint name="Manipulator_J5_Joint" type="revolute">
        <origin xyz="-0.000800000000000245 0 -0.3693" rpy="${pi/2} ${pi} 0" />
        <parent link="Manipulator_J4_Link" />
        <child link="Manipulator_J5_Link" />
        <axis xyz="0 0 1" />
        <limit
            lower="0.0"
            upper="${pi}"
            effort="1.0"
            velocity="1.0" />
    </joint>
<!-- ROBOT ARM JOINT 6-->
    <!--LINK 6 - 1-->
    <link name="Manipulator_J6_Link">
        <inertial>
            <origin xyz="0.00578093359019927 -0.000264987177930803 0.0796269506692188" rpy="0 0 0" />
            <mass value="0.611288792787516" />
            <inertia
                ixx="0.000832595437099927"
                ixy="1.94847589964478E-07"
                ixz="3.20541751060191E-05"
                iyy="0.000676267910001936"
                iyz="1.24697357653766E-06"
                izz="0.000591188269209395" />
        </inertial>
        <visual>
            <origin xyz="0 0 0" rpy="0 0 0" />
            <geometry>
                <mesh filename="file://$(find my_robot_hw)/meshes/Manipulator_J6_Link.STL" />
            </geometry>
            <material name="">
                <color rgba="0.109803921568627 0.109803921568627 0.109803921568627 1" />
            </material>
        </visual>
        <collision>
            <origin xyz="0 0 0" rpy="0 0 0" />
            <geometry>
                <mesh filename="file://$(find my_robot_hw)/meshes/Manipulator_J6_Link.STL" />
            </geometry>
        </collision>
    </link>
    <joint name="Manipulator_J6_Joint" type="revolute">
        <origin xyz="0.0522500000000208 0 0" rpy="-${pi/2} 0 -${pi/2}" />
        <parent link="Manipulator_J5_Link" />
        <child link="Manipulator_J6_Link" />
        <axis xyz="0 0 1" />
        <limit
            lower="0"
            upper="${2*pi}"
            effort="1.0"
            velocity="1.0" />
    </joint>

    <link name="Gripper">
        <inertial>
            <origin xyz="-6.73226762266249E-06 -4.21790802085376E-06 0.0900723392705949" rpy="0 0 0" />
            <mass value="0.4509022059942" />
            <inertia
                ixx="0.000236508648687378"
                ixy="6.32651513448348E-07"
                ixz="3.3491905263238E-09"
                iyy="0.000336539663481848"
                iyz="5.63026314340088E-11"
                izz="0.00021743931900608" />
        </inertial>
        <visual>
            <origin xyz="0 0 0" rpy="0 0 0" />
            <geometry>
                <mesh filename="file://$(find my_robot_hw)/meshes/Gripper.STL" />
            </geometry>
            <material name="">
                <color rgba="1 1 1 1" />
            </material>
        </visual>
        <collision>
            <origin xyz="0 0 0" rpy="0 0 0" />
            <geometry>
                <!-- <mesh filename="file://$(find my_robot_hw)/meshes/Gripper.STL" /> -->
                <box size="0.03 0.03 0.03"/>
            </geometry>
        </collision>
    </link>
    <joint name="Gripper" type="fixed">
        <origin xyz="-0.2096983371714 0 0.10775" rpy="-${pi/2} 0 -1.57103067053171" />
        <parent link="Manipulator_J6_Link" />
        <child link="Gripper" />
        <axis xyz="0 0 0" />
    </joint>


    <link name="Gripper_R">
 <inertial>
            <origin xyz="0 0 0" rpy="0 0 0" />
            <mass value="0.656515332445086" />
            <inertia
                ixx="0.000548812323732704"
                ixy="1.47501401739925E-06"
                ixz="5.29856422926262E-07"
                iyy="0.000687393677149892"
                iyz="1.33696209379453E-06"
                izz="0.000489604296478664" />
        </inertial>
        <visual>
            <origin xyz="0 0 0.03" rpy="0 0 0" />
            <geometry>
                <box size="0.01 0.01 0.06" />
            </geometry>
            <material name="">
                <color rgba="0.213 0.59 0.59 1"/>
            </material>
        </visual>
        <collision>
            <origin xyz="0 0 0.03" rpy="0 0 0" />
            <geometry>
                <box size="0.01 0.01 0.06" />
            </geometry>
        </collision>
    </link>
    <joint name="Gripper_R_Joint" type="prismatic">
        <origin xyz="-0.055 0 -0.045" rpy="0 0 0" />
        <parent link="Gripper" />
        <child link="Gripper_R" />
        <limit 
            lower="-0.005" 
            upper="0.05"
            effort="1.0"
            velocity="1.0"/>
    </joint>

    <link name="Gripper_L">
        <inertial>
            <origin xyz="0 0 0" rpy="0 0 0" />
            <mass value="0.656515332445086" />
            <inertia
                ixx="0.000548812323732704"
                ixy="1.47501401739925E-06"
                ixz="5.29856422926262E-07"
                iyy="0.000687393677149892"
                iyz="1.33696209379453E-06"
                izz="0.000489604296478664" />
        </inertial>
        <visual>
            <origin xyz="0 0 0.03" rpy="0 0 0" />
            <geometry>
                <box size="0.01 0.01 0.06" />
            </geometry>
            <material name="">
                <color rgba="0.213 0.59 0.59 1"/>
            </material>
        </visual>
        <collision>
            <origin xyz="0 0 0.03" rpy="0 0 0" />
            <geometry>
                <box size="0.01 0.01 0.06" />
            </geometry>
        </collision>
    </link>
    <joint name="Gripper_L_Joint" type="prismatic">
        <origin xyz="0.055 0 -0.045" rpy="0 0 0" />
        <parent link="Gripper" />
        <child link="Gripper_L" />
        <limit 
            lower="0.005" 
            upper="-0.045"
            effort="1.0"
            velocity="1.0"/>
        <mimic joint="Gripper_R_Joint" multiplier="-1" offset="0" />
    </joint>

</robot>
